{
 "PRed": [
  {
   "PR": {
    "__lazy_json__": "pr_json/926195731.json"
   },
   "data": {
    "bot_rerun": false,
    "migrator_name": "MigrationYaml",
    "migrator_object_version": 1,
    "migrator_version": 0,
    "name": "python310"
   },
   "keys": [
    "bot_rerun",
    "migrator_name",
    "migrator_object_version",
    "migrator_version",
    "name"
   ]
  },
  {
   "PR": {
    "__lazy_json__": "pr_json/926384097.json"
   },
   "data": {
    "bot_rerun": 1667404043.342655,
    "migrator_name": "MigrationYaml",
    "migrator_object_version": 1,
    "migrator_version": 0,
    "name": "pypy38"
   },
   "keys": [
    "bot_rerun",
    "migrator_name",
    "migrator_object_version",
    "migrator_version",
    "name"
   ]
  },
  {
   "PR": {
    "__lazy_json__": "pr_json/1107649879.json"
   },
   "data": {
    "bot_rerun": false,
    "migrator_name": "MigrationYaml",
    "migrator_object_version": 1,
    "migrator_version": 0,
    "name": "python311"
   },
   "keys": [
    "bot_rerun",
    "migrator_name",
    "migrator_object_version",
    "migrator_version",
    "name"
   ]
  },
  {
   "PR": {
    "__lazy_json__": "pr_json/1108540148.json"
   },
   "data": {
    "bot_rerun": false,
    "migrator_name": "MigrationYaml",
    "migrator_object_version": 1,
    "migrator_version": 0,
    "name": "pypy38"
   },
   "keys": [
    "bot_rerun",
    "migrator_name",
    "migrator_object_version",
    "migrator_version",
    "name"
   ]
  }
 ],
 "archived": false,
 "bad": "make_graph: render error cond build error: InvalidVersion(\"Invalid version: '3.8.* *_cpython'\")\nTraceback (most recent call last):\n  File \"/home/runner/work/autotick-bot/autotick-bot/cf-scripts/conda_forge_tick/utils.py\", line 194, in parse_meta_yaml\n    return _run(use_orig_cbc_path=True)\n  File \"/home/runner/work/autotick-bot/autotick-bot/cf-scripts/conda_forge_tick/utils.py\", line 181, in _run\n    return _parse_meta_yaml_impl(\n  File \"/home/runner/work/autotick-bot/autotick-bot/cf-scripts/conda_forge_tick/utils.py\", line 283, in _parse_meta_yaml_impl\n    m = MetaData(tmpdir, config=config, variant=var)\n  File \"/usr/share/miniconda3/envs/run_env/lib/python3.9/site-packages/conda_build/metadata.py\", line 1075, in __init__\n    self.parse_again(permit_undefined_jinja=True, allow_no_other_outputs=True)\n  File \"/usr/share/miniconda3/envs/run_env/lib/python3.9/site-packages/conda_build/metadata.py\", line 1167, in parse_again\n    self._get_contents(\n  File \"/usr/share/miniconda3/envs/run_env/lib/python3.9/site-packages/conda_build/metadata.py\", line 1836, in _get_contents\n    env.globals.update(ns_cfg(self.config))\n  File \"/usr/share/miniconda3/envs/run_env/lib/python3.9/site-packages/conda_build/metadata.py\", line 102, in ns_cfg\n    defaults = variants.get_default_variant(config)\n  File \"/usr/share/miniconda3/envs/run_env/lib/python3.9/site-packages/conda_build/variants.py\", line 109, in get_default_variant\n    base.update(_get_default_compilers(config.platform, python))\n  File \"/usr/share/miniconda3/envs/run_env/lib/python3.9/site-packages/conda_build/variants.py\", line 90, in _get_default_compilers\n    if parse_version(py_ver) >= parse_version('3.5'):\n  File \"/usr/share/miniconda3/envs/run_env/lib/python3.9/site-packages/pkg_resources/_vendor/packaging/version.py\", line 266, in __init__\n    raise InvalidVersion(f\"Invalid version: '{version}'\")\npkg_resources.extern.packaging.version.InvalidVersion: Invalid version: '3.8.* *_cpython'\n\nDuring handling of the above exception, another exception occurred:\n\nTraceback (most recent call last):\n  File \"/home/runner/work/autotick-bot/autotick-bot/cf-scripts/conda_forge_tick/utils.py\", line 198, in parse_meta_yaml\n    return _run(use_orig_cbc_path=False)\n  File \"/home/runner/work/autotick-bot/autotick-bot/cf-scripts/conda_forge_tick/utils.py\", line 181, in _run\n    return _parse_meta_yaml_impl(\n  File \"/home/runner/work/autotick-bot/autotick-bot/cf-scripts/conda_forge_tick/utils.py\", line 283, in _parse_meta_yaml_impl\n    m = MetaData(tmpdir, config=config, variant=var)\n  File \"/usr/share/miniconda3/envs/run_env/lib/python3.9/site-packages/conda_build/metadata.py\", line 1075, in __init__\n    self.parse_again(permit_undefined_jinja=True, allow_no_other_outputs=True)\n  File \"/usr/share/miniconda3/envs/run_env/lib/python3.9/site-packages/conda_build/metadata.py\", line 1167, in parse_again\n    self._get_contents(\n  File \"/usr/share/miniconda3/envs/run_env/lib/python3.9/site-packages/conda_build/metadata.py\", line 1836, in _get_contents\n    env.globals.update(ns_cfg(self.config))\n  File \"/usr/share/miniconda3/envs/run_env/lib/python3.9/site-packages/conda_build/metadata.py\", line 102, in ns_cfg\n    defaults = variants.get_default_variant(config)\n  File \"/usr/share/miniconda3/envs/run_env/lib/python3.9/site-packages/conda_build/variants.py\", line 109, in get_default_variant\n    base.update(_get_default_compilers(config.platform, python))\n  File \"/usr/share/miniconda3/envs/run_env/lib/python3.9/site-packages/conda_build/variants.py\", line 90, in _get_default_compilers\n    if parse_version(py_ver) >= parse_version('3.5'):\n  File \"/usr/share/miniconda3/envs/run_env/lib/python3.9/site-packages/pkg_resources/_vendor/packaging/version.py\", line 266, in __init__\n    raise InvalidVersion(f\"Invalid version: '{version}'\")\npkg_resources.extern.packaging.version.InvalidVersion: Invalid version: '3.8.* *_cpython'\n\nTraceback (most recent call last):\n  File \"/home/runner/work/autotick-bot/autotick-bot/cf-scripts/conda_forge_tick/utils.py\", line 194, in parse_meta_yaml\n    return _run(use_orig_cbc_path=True)\n  File \"/home/runner/work/autotick-bot/autotick-bot/cf-scripts/conda_forge_tick/utils.py\", line 181, in _run\n    return _parse_meta_yaml_impl(\n  File \"/home/runner/work/autotick-bot/autotick-bot/cf-scripts/conda_forge_tick/utils.py\", line 283, in _parse_meta_yaml_impl\n    m = MetaData(tmpdir, config=config, variant=var)\n  File \"/usr/share/miniconda3/envs/run_env/lib/python3.9/site-packages/conda_build/metadata.py\", line 1075, in __init__\n    self.parse_again(permit_undefined_jinja=True, allow_no_other_outputs=True)\n  File \"/usr/share/miniconda3/envs/run_env/lib/python3.9/site-packages/conda_build/metadata.py\", line 1167, in parse_again\n    self._get_contents(\n  File \"/usr/share/miniconda3/envs/run_env/lib/python3.9/site-packages/conda_build/metadata.py\", line 1836, in _get_contents\n    env.globals.update(ns_cfg(self.config))\n  File \"/usr/share/miniconda3/envs/run_env/lib/python3.9/site-packages/conda_build/metadata.py\", line 102, in ns_cfg\n    defaults = variants.get_default_variant(config)\n  File \"/usr/share/miniconda3/envs/run_env/lib/python3.9/site-packages/conda_build/variants.py\", line 109, in get_default_variant\n    base.update(_get_default_compilers(config.platform, python))\n  File \"/usr/share/miniconda3/envs/run_env/lib/python3.9/site-packages/conda_build/variants.py\", line 90, in _get_default_compilers\n    if parse_version(py_ver) >= parse_version('3.5'):\n  File \"/usr/share/miniconda3/envs/run_env/lib/python3.9/site-packages/pkg_resources/_vendor/packaging/version.py\", line 266, in __init__\n    raise InvalidVersion(f\"Invalid version: '{version}'\")\npkg_resources.extern.packaging.version.InvalidVersion: Invalid version: '3.8.* *_cpython'\n\nDuring handling of the above exception, another exception occurred:\n\nTraceback (most recent call last):\n  File \"/home/runner/work/autotick-bot/autotick-bot/cf-scripts/conda_forge_tick/utils.py\", line 198, in parse_meta_yaml\n    return _run(use_orig_cbc_path=False)\n  File \"/home/runner/work/autotick-bot/autotick-bot/cf-scripts/conda_forge_tick/utils.py\", line 181, in _run\n    return _parse_meta_yaml_impl(\n  File \"/home/runner/work/autotick-bot/autotick-bot/cf-scripts/conda_forge_tick/utils.py\", line 283, in _parse_meta_yaml_impl\n    m = MetaData(tmpdir, config=config, variant=var)\n  File \"/usr/share/miniconda3/envs/run_env/lib/python3.9/site-packages/conda_build/metadata.py\", line 1075, in __init__\n    self.parse_again(permit_undefined_jinja=True, allow_no_other_outputs=True)\n  File \"/usr/share/miniconda3/envs/run_env/lib/python3.9/site-packages/conda_build/metadata.py\", line 1167, in parse_again\n    self._get_contents(\n  File \"/usr/share/miniconda3/envs/run_env/lib/python3.9/site-packages/conda_build/metadata.py\", line 1836, in _get_contents\n    env.globals.update(ns_cfg(self.config))\n  File \"/usr/share/miniconda3/envs/run_env/lib/python3.9/site-packages/conda_build/metadata.py\", line 102, in ns_cfg\n    defaults = variants.get_default_variant(config)\n  File \"/usr/share/miniconda3/envs/run_env/lib/python3.9/site-packages/conda_build/variants.py\", line 109, in get_default_variant\n    base.update(_get_default_compilers(config.platform, python))\n  File \"/usr/share/miniconda3/envs/run_env/lib/python3.9/site-packages/conda_build/variants.py\", line 90, in _get_default_compilers\n    if parse_version(py_ver) >= parse_version('3.5'):\n  File \"/usr/share/miniconda3/envs/run_env/lib/python3.9/site-packages/pkg_resources/_vendor/packaging/version.py\", line 266, in __init__\n    raise InvalidVersion(f\"Invalid version: '{version}'\")\npkg_resources.extern.packaging.version.InvalidVersion: Invalid version: '3.8.* *_cpython'\n\nDuring handling of the above exception, another exception occurred:\n\nTraceback (most recent call last):\n  File \"/home/runner/work/autotick-bot/autotick-bot/cf-scripts/conda_forge_tick/feedstock_parser.py\", line 246, in populate_feedstock_attributes\n    parse_meta_yaml(\n  File \"/home/runner/work/autotick-bot/autotick-bot/cf-scripts/conda_forge_tick/utils.py\", line 200, in parse_meta_yaml\n    raise RuntimeError(\nRuntimeError: cond build error: InvalidVersion(\"Invalid version: '3.8.* *_cpython'\")\nTraceback (most recent call last):\n  File \"/home/runner/work/autotick-bot/autotick-bot/cf-scripts/conda_forge_tick/utils.py\", line 194, in parse_meta_yaml\n    return _run(use_orig_cbc_path=True)\n  File \"/home/runner/work/autotick-bot/autotick-bot/cf-scripts/conda_forge_tick/utils.py\", line 181, in _run\n    return _parse_meta_yaml_impl(\n  File \"/home/runner/work/autotick-bot/autotick-bot/cf-scripts/conda_forge_tick/utils.py\", line 283, in _parse_meta_yaml_impl\n    m = MetaData(tmpdir, config=config, variant=var)\n  File \"/usr/share/miniconda3/envs/run_env/lib/python3.9/site-packages/conda_build/metadata.py\", line 1075, in __init__\n    self.parse_again(permit_undefined_jinja=True, allow_no_other_outputs=True)\n  File \"/usr/share/miniconda3/envs/run_env/lib/python3.9/site-packages/conda_build/metadata.py\", line 1167, in parse_again\n    self._get_contents(\n  File \"/usr/share/miniconda3/envs/run_env/lib/python3.9/site-packages/conda_build/metadata.py\", line 1836, in _get_contents\n    env.globals.update(ns_cfg(self.config))\n  File \"/usr/share/miniconda3/envs/run_env/lib/python3.9/site-packages/conda_build/metadata.py\", line 102, in ns_cfg\n    defaults = variants.get_default_variant(config)\n  File \"/usr/share/miniconda3/envs/run_env/lib/python3.9/site-packages/conda_build/variants.py\", line 109, in get_default_variant\n    base.update(_get_default_compilers(config.platform, python))\n  File \"/usr/share/miniconda3/envs/run_env/lib/python3.9/site-packages/conda_build/variants.py\", line 90, in _get_default_compilers\n    if parse_version(py_ver) >= parse_version('3.5'):\n  File \"/usr/share/miniconda3/envs/run_env/lib/python3.9/site-packages/pkg_resources/_vendor/packaging/version.py\", line 266, in __init__\n    raise InvalidVersion(f\"Invalid version: '{version}'\")\npkg_resources.extern.packaging.version.InvalidVersion: Invalid version: '3.8.* *_cpython'\n\nDuring handling of the above exception, another exception occurred:\n\nTraceback (most recent call last):\n  File \"/home/runner/work/autotick-bot/autotick-bot/cf-scripts/conda_forge_tick/utils.py\", line 198, in parse_meta_yaml\n    return _run(use_orig_cbc_path=False)\n  File \"/home/runner/work/autotick-bot/autotick-bot/cf-scripts/conda_forge_tick/utils.py\", line 181, in _run\n    return _parse_meta_yaml_impl(\n  File \"/home/runner/work/autotick-bot/autotick-bot/cf-scripts/conda_forge_tick/utils.py\", line 283, in _parse_meta_yaml_impl\n    m = MetaData(tmpdir, config=config, variant=var)\n  File \"/usr/share/miniconda3/envs/run_env/lib/python3.9/site-packages/conda_build/metadata.py\", line 1075, in __init__\n    self.parse_again(permit_undefined_jinja=True, allow_no_other_outputs=True)\n  File \"/usr/share/miniconda3/envs/run_env/lib/python3.9/site-packages/conda_build/metadata.py\", line 1167, in parse_again\n    self._get_contents(\n  File \"/usr/share/miniconda3/envs/run_env/lib/python3.9/site-packages/conda_build/metadata.py\", line 1836, in _get_contents\n    env.globals.update(ns_cfg(self.config))\n  File \"/usr/share/miniconda3/envs/run_env/lib/python3.9/site-packages/conda_build/metadata.py\", line 102, in ns_cfg\n    defaults = variants.get_default_variant(config)\n  File \"/usr/share/miniconda3/envs/run_env/lib/python3.9/site-packages/conda_build/variants.py\", line 109, in get_default_variant\n    base.update(_get_default_compilers(config.platform, python))\n  File \"/usr/share/miniconda3/envs/run_env/lib/python3.9/site-packages/conda_build/variants.py\", line 90, in _get_default_compilers\n    if parse_version(py_ver) >= parse_version('3.5'):\n  File \"/usr/share/miniconda3/envs/run_env/lib/python3.9/site-packages/pkg_resources/_vendor/packaging/version.py\", line 266, in __init__\n    raise InvalidVersion(f\"Invalid version: '{version}'\")\npkg_resources.extern.packaging.version.InvalidVersion: Invalid version: '3.8.* *_cpython'\n\n",
 "branch": "main",
 "conda-forge.yml": {},
 "feedstock_name": "cached_interpolate",
 "hash_type": "sha256",
 "name": "cached_interpolate",
 "new_version": "0.1.0",
 "outputs_names": {
  "__set__": true,
  "elements": [
   "cached_interpolate"
  ]
 },
 "pinning_version": "2022.11.02.14.22.55",
 "pre_pr_migrator_attempts": {},
 "pre_pr_migrator_status": {},
 "raw_meta_yaml": "{% set name = \"cached_interpolate\" %}\n{% set version = \"0.1.0\" %}\n\npackage:\n  name: {{ name|lower }}\n  version: {{ version }}\n\nsource:\n  url: https://pypi.io/packages/source/{{ name[0] }}/{{ name }}/cached_interpolate-{{ version }}.tar.gz\n  sha256: f0782a2029f59fe67cf8dbfd8a85f5c62073817a62d5f6199e13f6eff70d2bb1\n\nbuild:\n  skip: true  # [py<37]\n  script: {{ PYTHON }} -m pip install . -vv\n  number: 3\n\nrequirements:\n  build:\n    - {{ compiler('c') }}\n  host:\n    - cython\n    - numpy\n    - pip\n    - python\n  run:\n    - python\n    - {{ pin_compatible('numpy') }}\n\ntest:\n  imports:\n    - cached_interpolate\n    - cached_interpolate.build\n  commands:\n    - pip check\n  requires:\n    - pip\n\nabout:\n  home: https://github.com/ColmTalbot/cached_interpolation\n  summary: Efficient repeated evaluation of splines at fixed points.\n  license: MIT\n  license_file: LICENSE\n\nextra:\n  recipe-maintainers:\n    - ColmTalbot\n",
 "smithy_version": "3.21.3",
 "strong_exports": false,
 "url": "https://pypi.io/packages/source/c/cached_interpolate/cached_interpolate-0.1.0.tar.gz",
 "version": "0.1.0"
}