{
 "PRed": [
  {
   "PR": {
    "__lazy_json__": "pr_json/805672098.json"
   },
   "data": {
    "bot_rerun": false,
    "migrator_name": "MigrationYaml",
    "migrator_object_version": 1,
    "migrator_version": 0,
    "name": "python310"
   },
   "keys": [
    "bot_rerun",
    "migrator_name",
    "migrator_object_version",
    "migrator_version",
    "name"
   ]
  },
  {
   "PR": {
    "__lazy_json__": "pr_json/807963748.json"
   },
   "data": {
    "bot_rerun": false,
    "migrator_name": "Version",
    "migrator_version": 0,
    "version": "2.3.3"
   },
   "keys": [
    "bot_rerun",
    "migrator_name",
    "migrator_version",
    "version"
   ]
  },
  {
   "PR": {
    "__lazy_json__": "pr_json/808263487.json"
   },
   "data": {
    "bot_rerun": false,
    "migrator_name": "Version",
    "migrator_version": 0,
    "version": "2.3.4"
   },
   "keys": [
    "bot_rerun",
    "migrator_name",
    "migrator_version",
    "version"
   ]
  },
  {
   "PR": {
    "__lazy_json__": "pr_json/831443748.json"
   },
   "data": {
    "bot_rerun": false,
    "migrator_name": "Version",
    "migrator_version": 0,
    "version": "2.3.5"
   },
   "keys": [
    "bot_rerun",
    "migrator_name",
    "migrator_version",
    "version"
   ]
  },
  {
   "PR": {
    "__lazy_json__": "pr_json/835251352.json"
   },
   "data": {
    "bot_rerun": false,
    "migrator_name": "Version",
    "migrator_version": 0,
    "version": "2.3.6"
   },
   "keys": [
    "bot_rerun",
    "migrator_name",
    "migrator_version",
    "version"
   ]
  },
  {
   "PR": {
    "__lazy_json__": "pr_json/969274021.json"
   },
   "data": {
    "bot_rerun": false,
    "migrator_name": "Version",
    "migrator_version": 0,
    "version": "2.3.7"
   },
   "keys": [
    "bot_rerun",
    "migrator_name",
    "migrator_version",
    "version"
   ]
  },
  {
   "PR": {
    "__lazy_json__": "pr_json/972651580.json"
   },
   "data": {
    "bot_rerun": false,
    "migrator_name": "Version",
    "migrator_version": 0,
    "version": "2.3.9"
   },
   "keys": [
    "bot_rerun",
    "migrator_name",
    "migrator_version",
    "version"
   ]
  },
  {
   "PR": {
    "__lazy_json__": "pr_json/1038362154.json"
   },
   "data": {
    "bot_rerun": false,
    "migrator_name": "MigrationYaml",
    "migrator_object_version": 1,
    "migrator_version": 0,
    "name": "pypy38"
   },
   "keys": [
    "bot_rerun",
    "migrator_name",
    "migrator_object_version",
    "migrator_version",
    "name"
   ]
  },
  {
   "PR": {
    "__lazy_json__": "pr_json/1080888805.json"
   },
   "data": {
    "bot_rerun": false,
    "migrator_name": "Version",
    "migrator_version": 0,
    "version": "2.3.10"
   },
   "keys": [
    "bot_rerun",
    "migrator_name",
    "migrator_version",
    "version"
   ]
  },
  {
   "PR": {
    "__lazy_json__": "pr_json/1112171391.json"
   },
   "data": {
    "bot_rerun": false,
    "migrator_name": "MigrationYaml",
    "migrator_object_version": 1,
    "migrator_version": 0,
    "name": "python311"
   },
   "keys": [
    "bot_rerun",
    "migrator_name",
    "migrator_object_version",
    "migrator_version",
    "name"
   ]
  }
 ],
 "archived": false,
 "bad": "make_graph: render error cond build error: InvalidVersion(\"Invalid version: '3.8.* *_cpython'\")\nTraceback (most recent call last):\n  File \"/home/runner/work/autotick-bot/autotick-bot/cf-scripts/conda_forge_tick/utils.py\", line 194, in parse_meta_yaml\n    return _run(use_orig_cbc_path=True)\n  File \"/home/runner/work/autotick-bot/autotick-bot/cf-scripts/conda_forge_tick/utils.py\", line 181, in _run\n    return _parse_meta_yaml_impl(\n  File \"/home/runner/work/autotick-bot/autotick-bot/cf-scripts/conda_forge_tick/utils.py\", line 283, in _parse_meta_yaml_impl\n    m = MetaData(tmpdir, config=config, variant=var)\n  File \"/usr/share/miniconda3/envs/run_env/lib/python3.9/site-packages/conda_build/metadata.py\", line 1075, in __init__\n    self.parse_again(permit_undefined_jinja=True, allow_no_other_outputs=True)\n  File \"/usr/share/miniconda3/envs/run_env/lib/python3.9/site-packages/conda_build/metadata.py\", line 1167, in parse_again\n    self._get_contents(\n  File \"/usr/share/miniconda3/envs/run_env/lib/python3.9/site-packages/conda_build/metadata.py\", line 1836, in _get_contents\n    env.globals.update(ns_cfg(self.config))\n  File \"/usr/share/miniconda3/envs/run_env/lib/python3.9/site-packages/conda_build/metadata.py\", line 102, in ns_cfg\n    defaults = variants.get_default_variant(config)\n  File \"/usr/share/miniconda3/envs/run_env/lib/python3.9/site-packages/conda_build/variants.py\", line 109, in get_default_variant\n    base.update(_get_default_compilers(config.platform, python))\n  File \"/usr/share/miniconda3/envs/run_env/lib/python3.9/site-packages/conda_build/variants.py\", line 90, in _get_default_compilers\n    if parse_version(py_ver) >= parse_version('3.5'):\n  File \"/usr/share/miniconda3/envs/run_env/lib/python3.9/site-packages/pkg_resources/_vendor/packaging/version.py\", line 266, in __init__\n    raise InvalidVersion(f\"Invalid version: '{version}'\")\npkg_resources.extern.packaging.version.InvalidVersion: Invalid version: '3.8.* *_cpython'\n\nDuring handling of the above exception, another exception occurred:\n\nTraceback (most recent call last):\n  File \"/home/runner/work/autotick-bot/autotick-bot/cf-scripts/conda_forge_tick/utils.py\", line 198, in parse_meta_yaml\n    return _run(use_orig_cbc_path=False)\n  File \"/home/runner/work/autotick-bot/autotick-bot/cf-scripts/conda_forge_tick/utils.py\", line 181, in _run\n    return _parse_meta_yaml_impl(\n  File \"/home/runner/work/autotick-bot/autotick-bot/cf-scripts/conda_forge_tick/utils.py\", line 283, in _parse_meta_yaml_impl\n    m = MetaData(tmpdir, config=config, variant=var)\n  File \"/usr/share/miniconda3/envs/run_env/lib/python3.9/site-packages/conda_build/metadata.py\", line 1075, in __init__\n    self.parse_again(permit_undefined_jinja=True, allow_no_other_outputs=True)\n  File \"/usr/share/miniconda3/envs/run_env/lib/python3.9/site-packages/conda_build/metadata.py\", line 1167, in parse_again\n    self._get_contents(\n  File \"/usr/share/miniconda3/envs/run_env/lib/python3.9/site-packages/conda_build/metadata.py\", line 1836, in _get_contents\n    env.globals.update(ns_cfg(self.config))\n  File \"/usr/share/miniconda3/envs/run_env/lib/python3.9/site-packages/conda_build/metadata.py\", line 102, in ns_cfg\n    defaults = variants.get_default_variant(config)\n  File \"/usr/share/miniconda3/envs/run_env/lib/python3.9/site-packages/conda_build/variants.py\", line 109, in get_default_variant\n    base.update(_get_default_compilers(config.platform, python))\n  File \"/usr/share/miniconda3/envs/run_env/lib/python3.9/site-packages/conda_build/variants.py\", line 90, in _get_default_compilers\n    if parse_version(py_ver) >= parse_version('3.5'):\n  File \"/usr/share/miniconda3/envs/run_env/lib/python3.9/site-packages/pkg_resources/_vendor/packaging/version.py\", line 266, in __init__\n    raise InvalidVersion(f\"Invalid version: '{version}'\")\npkg_resources.extern.packaging.version.InvalidVersion: Invalid version: '3.8.* *_cpython'\n\nTraceback (most recent call last):\n  File \"/home/runner/work/autotick-bot/autotick-bot/cf-scripts/conda_forge_tick/utils.py\", line 194, in parse_meta_yaml\n    return _run(use_orig_cbc_path=True)\n  File \"/home/runner/work/autotick-bot/autotick-bot/cf-scripts/conda_forge_tick/utils.py\", line 181, in _run\n    return _parse_meta_yaml_impl(\n  File \"/home/runner/work/autotick-bot/autotick-bot/cf-scripts/conda_forge_tick/utils.py\", line 283, in _parse_meta_yaml_impl\n    m = MetaData(tmpdir, config=config, variant=var)\n  File \"/usr/share/miniconda3/envs/run_env/lib/python3.9/site-packages/conda_build/metadata.py\", line 1075, in __init__\n    self.parse_again(permit_undefined_jinja=True, allow_no_other_outputs=True)\n  File \"/usr/share/miniconda3/envs/run_env/lib/python3.9/site-packages/conda_build/metadata.py\", line 1167, in parse_again\n    self._get_contents(\n  File \"/usr/share/miniconda3/envs/run_env/lib/python3.9/site-packages/conda_build/metadata.py\", line 1836, in _get_contents\n    env.globals.update(ns_cfg(self.config))\n  File \"/usr/share/miniconda3/envs/run_env/lib/python3.9/site-packages/conda_build/metadata.py\", line 102, in ns_cfg\n    defaults = variants.get_default_variant(config)\n  File \"/usr/share/miniconda3/envs/run_env/lib/python3.9/site-packages/conda_build/variants.py\", line 109, in get_default_variant\n    base.update(_get_default_compilers(config.platform, python))\n  File \"/usr/share/miniconda3/envs/run_env/lib/python3.9/site-packages/conda_build/variants.py\", line 90, in _get_default_compilers\n    if parse_version(py_ver) >= parse_version('3.5'):\n  File \"/usr/share/miniconda3/envs/run_env/lib/python3.9/site-packages/pkg_resources/_vendor/packaging/version.py\", line 266, in __init__\n    raise InvalidVersion(f\"Invalid version: '{version}'\")\npkg_resources.extern.packaging.version.InvalidVersion: Invalid version: '3.8.* *_cpython'\n\nDuring handling of the above exception, another exception occurred:\n\nTraceback (most recent call last):\n  File \"/home/runner/work/autotick-bot/autotick-bot/cf-scripts/conda_forge_tick/utils.py\", line 198, in parse_meta_yaml\n    return _run(use_orig_cbc_path=False)\n  File \"/home/runner/work/autotick-bot/autotick-bot/cf-scripts/conda_forge_tick/utils.py\", line 181, in _run\n    return _parse_meta_yaml_impl(\n  File \"/home/runner/work/autotick-bot/autotick-bot/cf-scripts/conda_forge_tick/utils.py\", line 283, in _parse_meta_yaml_impl\n    m = MetaData(tmpdir, config=config, variant=var)\n  File \"/usr/share/miniconda3/envs/run_env/lib/python3.9/site-packages/conda_build/metadata.py\", line 1075, in __init__\n    self.parse_again(permit_undefined_jinja=True, allow_no_other_outputs=True)\n  File \"/usr/share/miniconda3/envs/run_env/lib/python3.9/site-packages/conda_build/metadata.py\", line 1167, in parse_again\n    self._get_contents(\n  File \"/usr/share/miniconda3/envs/run_env/lib/python3.9/site-packages/conda_build/metadata.py\", line 1836, in _get_contents\n    env.globals.update(ns_cfg(self.config))\n  File \"/usr/share/miniconda3/envs/run_env/lib/python3.9/site-packages/conda_build/metadata.py\", line 102, in ns_cfg\n    defaults = variants.get_default_variant(config)\n  File \"/usr/share/miniconda3/envs/run_env/lib/python3.9/site-packages/conda_build/variants.py\", line 109, in get_default_variant\n    base.update(_get_default_compilers(config.platform, python))\n  File \"/usr/share/miniconda3/envs/run_env/lib/python3.9/site-packages/conda_build/variants.py\", line 90, in _get_default_compilers\n    if parse_version(py_ver) >= parse_version('3.5'):\n  File \"/usr/share/miniconda3/envs/run_env/lib/python3.9/site-packages/pkg_resources/_vendor/packaging/version.py\", line 266, in __init__\n    raise InvalidVersion(f\"Invalid version: '{version}'\")\npkg_resources.extern.packaging.version.InvalidVersion: Invalid version: '3.8.* *_cpython'\n\nDuring handling of the above exception, another exception occurred:\n\nTraceback (most recent call last):\n  File \"/home/runner/work/autotick-bot/autotick-bot/cf-scripts/conda_forge_tick/feedstock_parser.py\", line 246, in populate_feedstock_attributes\n    parse_meta_yaml(\n  File \"/home/runner/work/autotick-bot/autotick-bot/cf-scripts/conda_forge_tick/utils.py\", line 200, in parse_meta_yaml\n    raise RuntimeError(\nRuntimeError: cond build error: InvalidVersion(\"Invalid version: '3.8.* *_cpython'\")\nTraceback (most recent call last):\n  File \"/home/runner/work/autotick-bot/autotick-bot/cf-scripts/conda_forge_tick/utils.py\", line 194, in parse_meta_yaml\n    return _run(use_orig_cbc_path=True)\n  File \"/home/runner/work/autotick-bot/autotick-bot/cf-scripts/conda_forge_tick/utils.py\", line 181, in _run\n    return _parse_meta_yaml_impl(\n  File \"/home/runner/work/autotick-bot/autotick-bot/cf-scripts/conda_forge_tick/utils.py\", line 283, in _parse_meta_yaml_impl\n    m = MetaData(tmpdir, config=config, variant=var)\n  File \"/usr/share/miniconda3/envs/run_env/lib/python3.9/site-packages/conda_build/metadata.py\", line 1075, in __init__\n    self.parse_again(permit_undefined_jinja=True, allow_no_other_outputs=True)\n  File \"/usr/share/miniconda3/envs/run_env/lib/python3.9/site-packages/conda_build/metadata.py\", line 1167, in parse_again\n    self._get_contents(\n  File \"/usr/share/miniconda3/envs/run_env/lib/python3.9/site-packages/conda_build/metadata.py\", line 1836, in _get_contents\n    env.globals.update(ns_cfg(self.config))\n  File \"/usr/share/miniconda3/envs/run_env/lib/python3.9/site-packages/conda_build/metadata.py\", line 102, in ns_cfg\n    defaults = variants.get_default_variant(config)\n  File \"/usr/share/miniconda3/envs/run_env/lib/python3.9/site-packages/conda_build/variants.py\", line 109, in get_default_variant\n    base.update(_get_default_compilers(config.platform, python))\n  File \"/usr/share/miniconda3/envs/run_env/lib/python3.9/site-packages/conda_build/variants.py\", line 90, in _get_default_compilers\n    if parse_version(py_ver) >= parse_version('3.5'):\n  File \"/usr/share/miniconda3/envs/run_env/lib/python3.9/site-packages/pkg_resources/_vendor/packaging/version.py\", line 266, in __init__\n    raise InvalidVersion(f\"Invalid version: '{version}'\")\npkg_resources.extern.packaging.version.InvalidVersion: Invalid version: '3.8.* *_cpython'\n\nDuring handling of the above exception, another exception occurred:\n\nTraceback (most recent call last):\n  File \"/home/runner/work/autotick-bot/autotick-bot/cf-scripts/conda_forge_tick/utils.py\", line 198, in parse_meta_yaml\n    return _run(use_orig_cbc_path=False)\n  File \"/home/runner/work/autotick-bot/autotick-bot/cf-scripts/conda_forge_tick/utils.py\", line 181, in _run\n    return _parse_meta_yaml_impl(\n  File \"/home/runner/work/autotick-bot/autotick-bot/cf-scripts/conda_forge_tick/utils.py\", line 283, in _parse_meta_yaml_impl\n    m = MetaData(tmpdir, config=config, variant=var)\n  File \"/usr/share/miniconda3/envs/run_env/lib/python3.9/site-packages/conda_build/metadata.py\", line 1075, in __init__\n    self.parse_again(permit_undefined_jinja=True, allow_no_other_outputs=True)\n  File \"/usr/share/miniconda3/envs/run_env/lib/python3.9/site-packages/conda_build/metadata.py\", line 1167, in parse_again\n    self._get_contents(\n  File \"/usr/share/miniconda3/envs/run_env/lib/python3.9/site-packages/conda_build/metadata.py\", line 1836, in _get_contents\n    env.globals.update(ns_cfg(self.config))\n  File \"/usr/share/miniconda3/envs/run_env/lib/python3.9/site-packages/conda_build/metadata.py\", line 102, in ns_cfg\n    defaults = variants.get_default_variant(config)\n  File \"/usr/share/miniconda3/envs/run_env/lib/python3.9/site-packages/conda_build/variants.py\", line 109, in get_default_variant\n    base.update(_get_default_compilers(config.platform, python))\n  File \"/usr/share/miniconda3/envs/run_env/lib/python3.9/site-packages/conda_build/variants.py\", line 90, in _get_default_compilers\n    if parse_version(py_ver) >= parse_version('3.5'):\n  File \"/usr/share/miniconda3/envs/run_env/lib/python3.9/site-packages/pkg_resources/_vendor/packaging/version.py\", line 266, in __init__\n    raise InvalidVersion(f\"Invalid version: '{version}'\")\npkg_resources.extern.packaging.version.InvalidVersion: Invalid version: '3.8.* *_cpython'\n\n",
 "branch": "main",
 "conda-forge.yml": {},
 "feedstock_name": "dtaidistance",
 "hash_type": "sha256",
 "name": "dtaidistance",
 "new_version": "2.3.10",
 "new_version_attempts": {
  "2.3.10": 1,
  "2.3.3": 1,
  "2.3.4": 1,
  "2.3.5": 1,
  "2.3.6": 1,
  "2.3.7": 1,
  "2.3.9": 1
 },
 "new_version_errors": {},
 "outputs_names": {
  "__set__": true,
  "elements": [
   "dtaidistance"
  ]
 },
 "pinning_version": "2022.11.06.17.50.32",
 "raw_meta_yaml": "{% set name = \"dtaidistance\" %}\n{% set version = \"2.3.10\" %}\n\npackage:\n  name: {{ name|lower }}\n  version: {{ version }}\n\nsource:\n  url: https://pypi.io/packages/source/{{ name[0] }}/{{ name }}/{{ name }}-{{ version }}.tar.gz\n  sha256: 0da309e34a4a8cc47ba3c84cffa072361917bb411a4b61cf7d3ffc2d457cbff2\n\nbuild:\n  number: 1\n  script: {{ PYTHON }} -m pip install . -vv\n\nrequirements:\n  build:\n    - {{ compiler('c') }}\n    - cython\n    - numpy\n    - llvm-openmp  # [osx]\n    - libgomp  # [linux]\n  host:\n    - cython\n    - numpy\n    - pip\n    - python\n    - setuptools\n    - wheel\n  run:\n    - {{ pin_compatible('numpy') }}\n    - matplotlib-base >=3.0.0\n    - python\n    - scipy\n\ntest:\n  imports:\n    - dtaidistance\n    - dtaidistance.clustering\n    - dtaidistance.dtw\n    - dtaidistance.dtw_cc\n    - dtaidistance.dtw_cc_numpy\n    - dtaidistance.dtw_cc_omp\n    - dtaidistance.ed_cc\n\nabout:\n  home: https://github.com/wannesm/dtaidistance\n  license: Apache-2.0\n  license_family: Apache\n  license_file: LICENSE\n  summary: Distance measures for time series\n  doc_url: https://dtaidistance.readthedocs.io/en/latest/\n  dev_url: https://github.com/wannesm/dtaidistance\n\nextra:\n  recipe-maintainers:\n    - wannesm\n    - m-rossi\n",
 "smithy_version": "3.21.3",
 "strong_exports": false,
 "url": "https://pypi.io/packages/source/d/dtaidistance/dtaidistance-2.3.10.tar.gz",
 "version": "2.3.10"
}