{
 "PRed": [
  {
   "PR": {
    "__lazy_json__": "pr_json/666355471.json"
   },
   "data": {
    "bot_rerun": 1623317047.3629827,
    "migrator_name": "MigrationYaml",
    "migrator_object_version": 1,
    "migrator_version": 0,
    "name": "pypy"
   },
   "keys": [
    "bot_rerun",
    "migrator_name",
    "migrator_object_version",
    "migrator_version",
    "name"
   ]
  },
  {
   "PR": {
    "__lazy_json__": "pr_json/666356991.json"
   },
   "data": {
    "bot_rerun": false,
    "migrator_name": "MigrationYaml",
    "migrator_object_version": 1,
    "migrator_version": 0,
    "name": "pypy37"
   },
   "keys": [
    "bot_rerun",
    "migrator_name",
    "migrator_object_version",
    "migrator_version",
    "name"
   ]
  },
  {
   "PR": {
    "__lazy_json__": "pr_json/666712811.json"
   },
   "data": {
    "bot_rerun": false,
    "migrator_name": "MigrationYaml",
    "migrator_object_version": 1,
    "migrator_version": 0,
    "name": "pypy"
   },
   "keys": [
    "bot_rerun",
    "migrator_name",
    "migrator_object_version",
    "migrator_version",
    "name"
   ]
  },
  {
   "PR": {
    "__lazy_json__": "pr_json/683005369.json"
   },
   "data": {
    "bot_rerun": 1636273546.0698926,
    "migrator_name": "MigrationYaml",
    "migrator_object_version": 1,
    "migrator_version": 0,
    "name": "pypy37-windows"
   },
   "keys": [
    "bot_rerun",
    "migrator_name",
    "migrator_object_version",
    "migrator_version",
    "name"
   ]
  },
  {
   "PR": {
    "__lazy_json__": "pr_json/774898705.json"
   },
   "data": {
    "bot_rerun": false,
    "migrator_name": "MigrationYaml",
    "migrator_object_version": 1,
    "migrator_version": 0,
    "name": "python310"
   },
   "keys": [
    "bot_rerun",
    "migrator_name",
    "migrator_object_version",
    "migrator_version",
    "name"
   ]
  },
  {
   "PR": {
    "__lazy_json__": "pr_json/908125787.json"
   },
   "data": {
    "bot_rerun": false,
    "migrator_name": "MigrationYaml",
    "migrator_object_version": 1,
    "migrator_version": 0,
    "name": "pypy38"
   },
   "keys": [
    "bot_rerun",
    "migrator_name",
    "migrator_object_version",
    "migrator_version",
    "name"
   ]
  },
  {
   "PR": {
    "__lazy_json__": "pr_json/1104301887.json"
   },
   "data": {
    "bot_rerun": false,
    "migrator_name": "MigrationYaml",
    "migrator_object_version": 1,
    "migrator_version": 0,
    "name": "python311"
   },
   "keys": [
    "bot_rerun",
    "migrator_name",
    "migrator_object_version",
    "migrator_version",
    "name"
   ]
  },
  {
   "PR": {
    "__lazy_json__": "pr_json/1197887185.json"
   },
   "data": {
    "bot_rerun": false,
    "migrator_name": "Version",
    "migrator_version": 0,
    "version": "1.2.14"
   },
   "keys": [
    "bot_rerun",
    "migrator_name",
    "migrator_version",
    "version"
   ]
  },
  {
   "PR": {
    "__lazy_json__": "pr_json/1197921608.json"
   },
   "data": {
    "bot_rerun": 1673783926.5397196,
    "migrator_name": "Version",
    "migrator_version": 0,
    "version": "1.2.15"
   },
   "keys": [
    "bot_rerun",
    "migrator_name",
    "migrator_version",
    "version"
   ]
  },
  {
   "PR": {
    "__lazy_json__": "pr_json/1198004016.json"
   },
   "data": {
    "bot_rerun": false,
    "migrator_name": "Version",
    "migrator_version": 0,
    "version": "1.2.15"
   },
   "keys": [
    "bot_rerun",
    "migrator_name",
    "migrator_version",
    "version"
   ]
  }
 ],
 "archived": false,
 "bad": "make_graph: render error cond build error: InvalidVersion(\"Invalid version: '3.8.* *_cpython'\")\nTraceback (most recent call last):\n  File \"/home/runner/work/autotick-bot/autotick-bot/cf-scripts/conda_forge_tick/utils.py\", line 194, in parse_meta_yaml\n    return _run(use_orig_cbc_path=True)\n  File \"/home/runner/work/autotick-bot/autotick-bot/cf-scripts/conda_forge_tick/utils.py\", line 181, in _run\n    return _parse_meta_yaml_impl(\n  File \"/home/runner/work/autotick-bot/autotick-bot/cf-scripts/conda_forge_tick/utils.py\", line 283, in _parse_meta_yaml_impl\n    m = MetaData(tmpdir, config=config, variant=var)\n  File \"/usr/share/miniconda3/envs/run_env/lib/python3.9/site-packages/conda_build/metadata.py\", line 1075, in __init__\n    self.parse_again(permit_undefined_jinja=True, allow_no_other_outputs=True)\n  File \"/usr/share/miniconda3/envs/run_env/lib/python3.9/site-packages/conda_build/metadata.py\", line 1167, in parse_again\n    self._get_contents(\n  File \"/usr/share/miniconda3/envs/run_env/lib/python3.9/site-packages/conda_build/metadata.py\", line 1836, in _get_contents\n    env.globals.update(ns_cfg(self.config))\n  File \"/usr/share/miniconda3/envs/run_env/lib/python3.9/site-packages/conda_build/metadata.py\", line 102, in ns_cfg\n    defaults = variants.get_default_variant(config)\n  File \"/usr/share/miniconda3/envs/run_env/lib/python3.9/site-packages/conda_build/variants.py\", line 109, in get_default_variant\n    base.update(_get_default_compilers(config.platform, python))\n  File \"/usr/share/miniconda3/envs/run_env/lib/python3.9/site-packages/conda_build/variants.py\", line 90, in _get_default_compilers\n    if parse_version(py_ver) >= parse_version('3.5'):\n  File \"/usr/share/miniconda3/envs/run_env/lib/python3.9/site-packages/pkg_resources/_vendor/packaging/version.py\", line 266, in __init__\n    raise InvalidVersion(f\"Invalid version: '{version}'\")\npkg_resources.extern.packaging.version.InvalidVersion: Invalid version: '3.8.* *_cpython'\n\nDuring handling of the above exception, another exception occurred:\n\nTraceback (most recent call last):\n  File \"/home/runner/work/autotick-bot/autotick-bot/cf-scripts/conda_forge_tick/utils.py\", line 198, in parse_meta_yaml\n    return _run(use_orig_cbc_path=False)\n  File \"/home/runner/work/autotick-bot/autotick-bot/cf-scripts/conda_forge_tick/utils.py\", line 181, in _run\n    return _parse_meta_yaml_impl(\n  File \"/home/runner/work/autotick-bot/autotick-bot/cf-scripts/conda_forge_tick/utils.py\", line 283, in _parse_meta_yaml_impl\n    m = MetaData(tmpdir, config=config, variant=var)\n  File \"/usr/share/miniconda3/envs/run_env/lib/python3.9/site-packages/conda_build/metadata.py\", line 1075, in __init__\n    self.parse_again(permit_undefined_jinja=True, allow_no_other_outputs=True)\n  File \"/usr/share/miniconda3/envs/run_env/lib/python3.9/site-packages/conda_build/metadata.py\", line 1167, in parse_again\n    self._get_contents(\n  File \"/usr/share/miniconda3/envs/run_env/lib/python3.9/site-packages/conda_build/metadata.py\", line 1836, in _get_contents\n    env.globals.update(ns_cfg(self.config))\n  File \"/usr/share/miniconda3/envs/run_env/lib/python3.9/site-packages/conda_build/metadata.py\", line 102, in ns_cfg\n    defaults = variants.get_default_variant(config)\n  File \"/usr/share/miniconda3/envs/run_env/lib/python3.9/site-packages/conda_build/variants.py\", line 109, in get_default_variant\n    base.update(_get_default_compilers(config.platform, python))\n  File \"/usr/share/miniconda3/envs/run_env/lib/python3.9/site-packages/conda_build/variants.py\", line 90, in _get_default_compilers\n    if parse_version(py_ver) >= parse_version('3.5'):\n  File \"/usr/share/miniconda3/envs/run_env/lib/python3.9/site-packages/pkg_resources/_vendor/packaging/version.py\", line 266, in __init__\n    raise InvalidVersion(f\"Invalid version: '{version}'\")\npkg_resources.extern.packaging.version.InvalidVersion: Invalid version: '3.8.* *_cpython'\n\nTraceback (most recent call last):\n  File \"/home/runner/work/autotick-bot/autotick-bot/cf-scripts/conda_forge_tick/utils.py\", line 194, in parse_meta_yaml\n    return _run(use_orig_cbc_path=True)\n  File \"/home/runner/work/autotick-bot/autotick-bot/cf-scripts/conda_forge_tick/utils.py\", line 181, in _run\n    return _parse_meta_yaml_impl(\n  File \"/home/runner/work/autotick-bot/autotick-bot/cf-scripts/conda_forge_tick/utils.py\", line 283, in _parse_meta_yaml_impl\n    m = MetaData(tmpdir, config=config, variant=var)\n  File \"/usr/share/miniconda3/envs/run_env/lib/python3.9/site-packages/conda_build/metadata.py\", line 1075, in __init__\n    self.parse_again(permit_undefined_jinja=True, allow_no_other_outputs=True)\n  File \"/usr/share/miniconda3/envs/run_env/lib/python3.9/site-packages/conda_build/metadata.py\", line 1167, in parse_again\n    self._get_contents(\n  File \"/usr/share/miniconda3/envs/run_env/lib/python3.9/site-packages/conda_build/metadata.py\", line 1836, in _get_contents\n    env.globals.update(ns_cfg(self.config))\n  File \"/usr/share/miniconda3/envs/run_env/lib/python3.9/site-packages/conda_build/metadata.py\", line 102, in ns_cfg\n    defaults = variants.get_default_variant(config)\n  File \"/usr/share/miniconda3/envs/run_env/lib/python3.9/site-packages/conda_build/variants.py\", line 109, in get_default_variant\n    base.update(_get_default_compilers(config.platform, python))\n  File \"/usr/share/miniconda3/envs/run_env/lib/python3.9/site-packages/conda_build/variants.py\", line 90, in _get_default_compilers\n    if parse_version(py_ver) >= parse_version('3.5'):\n  File \"/usr/share/miniconda3/envs/run_env/lib/python3.9/site-packages/pkg_resources/_vendor/packaging/version.py\", line 266, in __init__\n    raise InvalidVersion(f\"Invalid version: '{version}'\")\npkg_resources.extern.packaging.version.InvalidVersion: Invalid version: '3.8.* *_cpython'\n\nDuring handling of the above exception, another exception occurred:\n\nTraceback (most recent call last):\n  File \"/home/runner/work/autotick-bot/autotick-bot/cf-scripts/conda_forge_tick/utils.py\", line 198, in parse_meta_yaml\n    return _run(use_orig_cbc_path=False)\n  File \"/home/runner/work/autotick-bot/autotick-bot/cf-scripts/conda_forge_tick/utils.py\", line 181, in _run\n    return _parse_meta_yaml_impl(\n  File \"/home/runner/work/autotick-bot/autotick-bot/cf-scripts/conda_forge_tick/utils.py\", line 283, in _parse_meta_yaml_impl\n    m = MetaData(tmpdir, config=config, variant=var)\n  File \"/usr/share/miniconda3/envs/run_env/lib/python3.9/site-packages/conda_build/metadata.py\", line 1075, in __init__\n    self.parse_again(permit_undefined_jinja=True, allow_no_other_outputs=True)\n  File \"/usr/share/miniconda3/envs/run_env/lib/python3.9/site-packages/conda_build/metadata.py\", line 1167, in parse_again\n    self._get_contents(\n  File \"/usr/share/miniconda3/envs/run_env/lib/python3.9/site-packages/conda_build/metadata.py\", line 1836, in _get_contents\n    env.globals.update(ns_cfg(self.config))\n  File \"/usr/share/miniconda3/envs/run_env/lib/python3.9/site-packages/conda_build/metadata.py\", line 102, in ns_cfg\n    defaults = variants.get_default_variant(config)\n  File \"/usr/share/miniconda3/envs/run_env/lib/python3.9/site-packages/conda_build/variants.py\", line 109, in get_default_variant\n    base.update(_get_default_compilers(config.platform, python))\n  File \"/usr/share/miniconda3/envs/run_env/lib/python3.9/site-packages/conda_build/variants.py\", line 90, in _get_default_compilers\n    if parse_version(py_ver) >= parse_version('3.5'):\n  File \"/usr/share/miniconda3/envs/run_env/lib/python3.9/site-packages/pkg_resources/_vendor/packaging/version.py\", line 266, in __init__\n    raise InvalidVersion(f\"Invalid version: '{version}'\")\npkg_resources.extern.packaging.version.InvalidVersion: Invalid version: '3.8.* *_cpython'\n\nDuring handling of the above exception, another exception occurred:\n\nTraceback (most recent call last):\n  File \"/home/runner/work/autotick-bot/autotick-bot/cf-scripts/conda_forge_tick/feedstock_parser.py\", line 246, in populate_feedstock_attributes\n    parse_meta_yaml(\n  File \"/home/runner/work/autotick-bot/autotick-bot/cf-scripts/conda_forge_tick/utils.py\", line 200, in parse_meta_yaml\n    raise RuntimeError(\nRuntimeError: cond build error: InvalidVersion(\"Invalid version: '3.8.* *_cpython'\")\nTraceback (most recent call last):\n  File \"/home/runner/work/autotick-bot/autotick-bot/cf-scripts/conda_forge_tick/utils.py\", line 194, in parse_meta_yaml\n    return _run(use_orig_cbc_path=True)\n  File \"/home/runner/work/autotick-bot/autotick-bot/cf-scripts/conda_forge_tick/utils.py\", line 181, in _run\n    return _parse_meta_yaml_impl(\n  File \"/home/runner/work/autotick-bot/autotick-bot/cf-scripts/conda_forge_tick/utils.py\", line 283, in _parse_meta_yaml_impl\n    m = MetaData(tmpdir, config=config, variant=var)\n  File \"/usr/share/miniconda3/envs/run_env/lib/python3.9/site-packages/conda_build/metadata.py\", line 1075, in __init__\n    self.parse_again(permit_undefined_jinja=True, allow_no_other_outputs=True)\n  File \"/usr/share/miniconda3/envs/run_env/lib/python3.9/site-packages/conda_build/metadata.py\", line 1167, in parse_again\n    self._get_contents(\n  File \"/usr/share/miniconda3/envs/run_env/lib/python3.9/site-packages/conda_build/metadata.py\", line 1836, in _get_contents\n    env.globals.update(ns_cfg(self.config))\n  File \"/usr/share/miniconda3/envs/run_env/lib/python3.9/site-packages/conda_build/metadata.py\", line 102, in ns_cfg\n    defaults = variants.get_default_variant(config)\n  File \"/usr/share/miniconda3/envs/run_env/lib/python3.9/site-packages/conda_build/variants.py\", line 109, in get_default_variant\n    base.update(_get_default_compilers(config.platform, python))\n  File \"/usr/share/miniconda3/envs/run_env/lib/python3.9/site-packages/conda_build/variants.py\", line 90, in _get_default_compilers\n    if parse_version(py_ver) >= parse_version('3.5'):\n  File \"/usr/share/miniconda3/envs/run_env/lib/python3.9/site-packages/pkg_resources/_vendor/packaging/version.py\", line 266, in __init__\n    raise InvalidVersion(f\"Invalid version: '{version}'\")\npkg_resources.extern.packaging.version.InvalidVersion: Invalid version: '3.8.* *_cpython'\n\nDuring handling of the above exception, another exception occurred:\n\nTraceback (most recent call last):\n  File \"/home/runner/work/autotick-bot/autotick-bot/cf-scripts/conda_forge_tick/utils.py\", line 198, in parse_meta_yaml\n    return _run(use_orig_cbc_path=False)\n  File \"/home/runner/work/autotick-bot/autotick-bot/cf-scripts/conda_forge_tick/utils.py\", line 181, in _run\n    return _parse_meta_yaml_impl(\n  File \"/home/runner/work/autotick-bot/autotick-bot/cf-scripts/conda_forge_tick/utils.py\", line 283, in _parse_meta_yaml_impl\n    m = MetaData(tmpdir, config=config, variant=var)\n  File \"/usr/share/miniconda3/envs/run_env/lib/python3.9/site-packages/conda_build/metadata.py\", line 1075, in __init__\n    self.parse_again(permit_undefined_jinja=True, allow_no_other_outputs=True)\n  File \"/usr/share/miniconda3/envs/run_env/lib/python3.9/site-packages/conda_build/metadata.py\", line 1167, in parse_again\n    self._get_contents(\n  File \"/usr/share/miniconda3/envs/run_env/lib/python3.9/site-packages/conda_build/metadata.py\", line 1836, in _get_contents\n    env.globals.update(ns_cfg(self.config))\n  File \"/usr/share/miniconda3/envs/run_env/lib/python3.9/site-packages/conda_build/metadata.py\", line 102, in ns_cfg\n    defaults = variants.get_default_variant(config)\n  File \"/usr/share/miniconda3/envs/run_env/lib/python3.9/site-packages/conda_build/variants.py\", line 109, in get_default_variant\n    base.update(_get_default_compilers(config.platform, python))\n  File \"/usr/share/miniconda3/envs/run_env/lib/python3.9/site-packages/conda_build/variants.py\", line 90, in _get_default_compilers\n    if parse_version(py_ver) >= parse_version('3.5'):\n  File \"/usr/share/miniconda3/envs/run_env/lib/python3.9/site-packages/pkg_resources/_vendor/packaging/version.py\", line 266, in __init__\n    raise InvalidVersion(f\"Invalid version: '{version}'\")\npkg_resources.extern.packaging.version.InvalidVersion: Invalid version: '3.8.* *_cpython'\n\n",
 "branch": "main",
 "conda-forge.yml": {},
 "feedstock_name": "pymaxflow",
 "hash_type": "sha256",
 "name": "pymaxflow",
 "new_version": "1.2.15",
 "new_version_attempts": {
  "1.2.14": 1,
  "1.2.15": 2
 },
 "new_version_errors": {},
 "outputs_names": {
  "__set__": true,
  "elements": [
   "pymaxflow"
  ]
 },
 "pinning_version": "2023.01.15.02.58.09",
 "raw_meta_yaml": "{% set name = \"PyMaxflow\" %}\n{% set version = \"1.2.14\" %}\n\n\npackage:\n  name: {{ name|lower }}\n  version: {{ version }}\n\nsource:\n  url: https://pypi.io/packages/source/{{ name[0] }}/{{ name }}/PyMaxflow-{{ version }}.tar.gz\n  sha256: 57ff9e198f700737e38557d7985e9c95678e7234b51091a0810c8cdd0b25cdf6\n\nbuild:\n  number: 0\n  script: {{ PYTHON }} -m pip install . -vv\n\nrequirements:\n  build:\n    - {{ compiler('c') }}\n    - {{ compiler('cxx') }}\n  host:\n    - cython\n    - numpy\n    - pip\n    - python\n  run:\n    - python\n    - {{ pin_compatible('numpy') }}\n\ntest:\n  imports:\n    - maxflow\n  commands:\n    - pip check\n  requires:\n    - pip\n\nabout:\n  home: https://github.com/pmneila/PyMaxflow\n  summary: A mincut/maxflow package for Python\n  license: GPL-3.0-or-later\n  license_file: LICENSE\n\nextra:\n  recipe-maintainers:\n    - martibosch\n",
 "smithy_version": "3.22.1",
 "strong_exports": false,
 "url": "https://pypi.io/packages/source/P/PyMaxflow/PyMaxflow-1.2.14.tar.gz",
 "version": "1.2.14"
}